Workbook

Sheet Processos
A1: Número do Processo | B1: Autor(es) | C1: Réu(s) | D1: Vara | E1: Município | F1: Tribunal | G1: Data do Ajuizamento | H1: Área do Direito | I1: Matéria Principal | J1: Objeto | K1: Valor da Causa | L1: Andamentos | M1: Situação | N1: Ativo | O1: Valor Arbitrado em Juízo | P1: Probabilidade | Q1: Valor Estimado | R1: Valor da Execução | S1: Custas Processuais | T1: Depósitos Recursais | U1: Garantias Processuais | V1: Resultado | W1: Valor Economizado | X1: Data do trânsito em julgado | Y1: Taxa de resolução (em dias) | Z1: Houve recurso da empresa? | AA1: Percentual de êxito | AB1: Reclamante terceirizado? | AC1: Outra(s) Parte(s) | AD1: Momento Atual | AE1: Último Andamento | AF1: Data de Citação | AG1: Fase | AH1: Classe | AI1: Assunto | AJ1: Valor do Acordo | AK1: Observações | AL1: Passivo Potencial | AM1: Passivo Potencial Atualizado | AN1: Ativo Potencial | AO1: Percentual de Provisão | AP1: Provisão Constituída | AQ1: Depósito Judicial Realizado? | AR1: CNPJ da Empresa Processada | AS1: Pagamento Realizado | AT1: Justificativa da Probabilidade | AU1: Grau de Tramitação
W2: =IF(OR(tblProcessos[[#This Row],[Ativo]]<>"Não",tblProcessos[[#This Row],[Valor da Causa]]="",tblProcessos[[#This Row],[Valor Estimado]]=""),"",tblProcessos[[#This Row],[Valor da Causa]]-tblProcessos[[#This Row],[Valor Estimado]]) | Y2: =IF(OR(tblProcessos[[#This Row],[Data do trânsito em julgado]]="",tblProcessos[[#This Row],[Data do Ajuizamento]]=""),"",tblProcessos[[#This Row],[Data do trânsito em julgado]]-tblProcessos[[#This Row],[Data do Ajuizamento]])

Sheet Parâmetros
A1: Parâmetro | B1: Valor
A2: Número de funcionários (headcount) | C2: Usado em 'Litígios por 100 funcionários'.
A3: Data de referência | C3: Data-base do relatório; usada nos 'novos ajuizamentos em 12 meses'.
A4: Fator de correção | C4: Multiplica o valor da causa total (vazio = sem correção).
A5: Empresas do grupo | C5: Nomes separados por ponto e vírgula.

Sheet Indicadores
A1: Indicador | B1: Valor | C1: Como é calculado
A2: Acervo
A3: Total de processos | B3: =COUNTA(tblProcessos[Número do Processo]) | C3: Linhas com número de processo.
A4: Processos ativos | B4: =COUNTIFS(tblProcessos[Ativo],"Sim") | C4: Coluna Ativo = Sim.
A5: Processos encerrados | B5: =COUNTIFS(tblProcessos[Ativo],"Não") | C5: Coluna Ativo = Não.
A6: Litígios por 100 funcionários | B6: =IF(N('Parâmetros'!$B$2)>0,B3/'Parâmetros'!$B$2*100,"") | C6: Total de processos ÷ número de funcionários × 100 (precisa do headcount em Parâmetros).
A7: Novos ajuizamentos em 12 meses | B7: =IF(N('Parâmetros'!$B$3)>0,COUNTIFS(tblProcessos[Data do Ajuizamento],">"&EDATE('Parâmetros'!$B$3,-12),tblProcessos[Data do Ajuizamento],"<="&'Parâmetros'!$B$3),"") | C7: Ajuizados nos 12 meses até a data de referência (Parâmetros).
A9: Tempo e recursos
A10: Tempo médio de resolução (dias) | B10: =IFERROR(AVERAGE(tblProcessos[[Taxa de resolução (em dias)]]),"") | C10: Média da Taxa de resolução (trânsito em julgado − ajuizamento).
A11: Mediana do tempo de resolução (dias) | B11: =IFERROR(MEDIAN(tblProcessos[[Taxa de resolução (em dias)]]),"") | C11: Mediana da Taxa de resolução.
A12: Processos com recurso da empresa | B12: =COUNTIFS(tblProcessos[[Houve recurso da empresa?]],"Sim") | C12: Coluna Houve recurso da empresa? = Sim.
A13: Processos decididos | B13: =B17+B18+B19+B20+B21 | C13: Soma dos cinco desfechos abaixo (não conta extinção sem mérito nem incompetência).
A14: Taxa de recurso | B14: =IF(B13>0,B12/B13,"") | C14: Processos com recurso da empresa ÷ decididos.
A16: Resultados
A17: Improcedentes | B17: =COUNTIFS(tblProcessos[Resultado],"Improcedente") | C17: Coluna Resultado = Improcedente.
A18: Arquivadas / desistência | B18: =COUNTIFS(tblProcessos[Resultado],"Arquivado / desistência") | C18: Coluna Resultado = Arquivado / desistência.
A19: Acordos | B19: =COUNTIFS(tblProcessos[Resultado],"Acordo") | C19: Coluna Resultado = Acordo.
A20: Parcialmente procedentes | B20: =COUNTIFS(tblProcessos[Resultado],"Parcialmente procedente") | C20: Coluna Resultado = Parcialmente procedente.
A21: Procedentes | B21: =COUNTIFS(tblProcessos[Resultado],"Procedente") | C21: Coluna Resultado = Procedente.
A22: Taxa de êxito | B22: =IF(B13>0,(B17+B18)/B13,"") | C22: (Improcedentes + arquivadas) ÷ decididos.
A23: % por acordo | B23: =IF(B13>0,B19/B13,"") | C23: Acordos ÷ decididos.
A25: Financeiro
A26: Valor da causa total | B26: =SUM(tblProcessos[Valor da Causa]) | C26: Soma da coluna Valor da Causa.
A27: Valor da causa total corrigido | B27: =IF(N('Parâmetros'!$B$4)>0,B26*'Parâmetros'!$B$4,B26) | C27: Valor da causa × fator de correção (Parâmetros).
A28: Valor da causa dos encerrados | B28: =SUMIFS(tblProcessos[Valor da Causa],tblProcessos[Ativo],"Não") | C28: Processos com Ativo = Não.
A29: Encerrados com valor realizado lançado | B29: =COUNTIFS(tblProcessos[Ativo],"Não",tblProcessos[Valor Arbitrado em Juízo],"<>")+COUNTIFS(tblProcessos[Ativo],"Não",tblProcessos[Valor Arbitrado em Juízo],"",tblProcessos[Valor da Execução],"<>") | C29: Têm valor arbitrado ou, se este estiver vazio, valor da execução.
A30: Encerrados sem valor lançado (fora da economia) | B30: =B5-B29 | C30: Ficam fora da economia para não inflá-la (acordo sem valor lançado etc.).
A31: Valor da causa dos encerrados com valor lançado | B31: =SUMIFS(tblProcessos[Valor da Causa],tblProcessos[Ativo],"Não",tblProcessos[Valor Arbitrado em Juízo],"<>")+SUMIFS(tblProcessos[Valor da Causa],tblProcessos[Ativo],"Não",tblProcessos[Valor Arbitrado em Juízo],"",tblProcessos[Valor da Execução],"<>") | C31: Base da economia efetiva.
A32: Valor realizado dos encerrados | B32: =SUMIFS(tblProcessos[Valor Arbitrado em Juízo],tblProcessos[Ativo],"Não")+SUMIFS(tblProcessos[Valor da Execução],tblProcessos[Ativo],"Não",tblProcessos[Valor Arbitrado em Juízo],"") | C32: Valor arbitrado em juízo, ou o valor da execução quando o arbitrado está vazio.
A33: Economia efetiva | B33: =B31-B32 | C33: Valor da causa − valor realizado, só dos encerrados com valor lançado.
A35: Contingência
A36: Passivo potencial total | B36: =SUM(tblProcessos[Passivo Potencial]) | C36: Soma da coluna Passivo Potencial.
A37: Passivo potencial dos processos ativos | B37: =SUMIFS(tblProcessos[Passivo Potencial],tblProcessos[Ativo],"Sim") | C37: Passivo Potencial dos processos com Ativo = Sim.
A38: Passivo potencial atualizado (encerrados) | B38: =SUM(tblProcessos[Passivo Potencial Atualizado]) | C38: Soma da coluna Passivo Potencial Atualizado (correção e juros).
A39: Provisão constituída total | B39: =SUM(tblProcessos[Provisão Constituída]) | C39: Soma da coluna Provisão Constituída.
A40: Ativo potencial total | B40: =SUM(tblProcessos[Ativo Potencial]) | C40: Soma da coluna Ativo Potencial (créditos).
A41: Passivo potencial (ativos): perda remota | B41: =SUMIFS(tblProcessos[Passivo Potencial],tblProcessos[Probabilidade],"Remota",tblProcessos[Ativo],"Sim") | C41: Passivo Potencial dos processos ativos com Probabilidade = Remota.
A42: Passivo potencial (ativos): perda possível | B42: =SUMIFS(tblProcessos[Passivo Potencial],tblProcessos[Probabilidade],"Possível",tblProcessos[Ativo],"Sim") | C42: Passivo Potencial dos processos ativos com Probabilidade = Possível.
A43: Passivo potencial (ativos): perda provável | B43: =SUMIFS(tblProcessos[Passivo Potencial],tblProcessos[Probabilidade],"Provável",tblProcessos[Ativo],"Sim") | C43: Passivo Potencial dos processos ativos com Probabilidade = Provável.
A44: Processos com depósito judicial | B44: =COUNTIFS(tblProcessos[[Depósito Judicial Realizado?]],"Sim") | C44: Coluna Depósito Judicial Realizado? = Sim.
...

Sheet Dashboard
A1: Resumo da carteira
A3: Processos | C3: Ativos | E3: Taxa de êxito | G3: Economia efetiva | I3: Passivo potencial | K3: Provisão constituída
A4: =Indicadores!B3 | C4: =Indicadores!B4 | E4: =Indicadores!B22 | G4: =Indicadores!B33 | I4: =Indicadores!B36 | K4: =Indicadores!B39

Sheet Histórico
A1: Data-base | B1: Total de processos | C1: Processos ativos | D1: Processos encerrados | E1: Valor da causa | F1: Valor estimado | G1: Valor economizado

Sheet Faltas da migração
A1: Grupo | B1: Campo | C1: Preenchidos | D1: Total | E1: Percentual | F1: Origem | G1: O que fazer

Sheet Campos não migrados
A1: Coluna de origem | B1: Processo | C1: Valor
